<?xml version="1.0" ?>
<!-- =================================================================================== -->
<!-- |    This document was autogenerated by xacro from hexapod.urdf.xacro             | -->
<!-- |    EDITING THIS FILE BY HAND IS NOT RECOMMENDED                                 | -->
<!-- =================================================================================== -->
<robot name="hexapod">
  <!-- Base link -->
  <link name="base_link">
    <inertial>
      <origin rpy="0 0 0" xyz="0 0 0"/>
      <mass value="3.0"/>
      <inertia ixx="0.02" ixy="0.0" ixz="0.0" iyy="0.02" iyz="0.0" izz="0.02"/>
    </inertial>
    <visual>
      <origin rpy="0 0 0" xyz="0 0 0.025"/>
      <geometry>
        <cylinder length="0.05" radius="0.18"/>
      </geometry>
      <material name="gray">
        <color rgba="0.6 0.6 0.6 1.0"/>
      </material>
    </visual>
    <collision>
      <origin rpy="0 0 0" xyz="0 0 0.025"/>
      <geometry>
        <cylinder length="0.05" radius="0.18"/>
      </geometry>
    </collision>
  </link>
  <!-- IMU Sensor (MPU9250) -->
  <link name="imu_link">
    <inertial>
      <mass value="0.001"/>
      <inertia ixx="1e-6" ixy="0" ixz="0" iyy="1e-6" iyz="0" izz="1e-6"/>
    </inertial>
    <sensor name="imu_sensor" type="imu">
      <always_on>true</always_on>
      <update_rate>50</update_rate>
      <visualize>true</visualize>
      <topic>imu</topic>
      <plugin filename="libgz-sim-imu-system.so" name="imu_plugin"/>
    </sensor>
  </link>
  <joint name="imu_joint" type="fixed">
    <origin rpy="0 0 0" xyz="0 0 0.07"/>
    <parent link="base_link"/>
    <child link="imu_link"/>
  </joint>
  <!-- LiDAR Sensor (YDLiDAR TG50) -->
  <link name="lidar_link">
    <inertial>
      <mass value="0.05"/>
      <inertia ixx="1e-4" ixy="0" ixz="0" iyy="1e-4" iyz="0" izz="1e-4"/>
    </inertial>
    <visual>
      <origin rpy="0 0 0" xyz="0 0 0"/>
      <geometry>
        <cylinder length="0.05" radius="0.04"/>
      </geometry>
      <material name="black">
        <color rgba="0.1 0.1 0.1 1.0"/>
      </material>
    </visual>
    <collision>
      <origin rpy="0 0 0" xyz="0 0 0"/>
      <geometry>
        <cylinder length="0.05" radius="0.04"/>
      </geometry>
    </collision>
    <sensor name="lidar_sensor" type="gpu_lidar">
      <update_rate>10</update_rate>
      <topic>scan</topic>
      <plugin filename="libgz-sim-ray-sensor-system.so" name="lidar_plugin"/>
    </sensor>
  </link>
  <joint name="lidar_joint" type="fixed">
    <origin rpy="0 0 0" xyz="0 0 0.1"/>
    <parent link="base_link"/>
    <child link="lidar_link"/>
  </joint>
  <!-- hip link -->
  <link name="leg_1_hip_link">
    <inertial>
      <origin rpy="0 1.5708 0" xyz="0.025 0 0"/>
      <mass value="0.05"/>
      <inertia ixx="1e-4" ixy="0" ixz="0" iyy="1e-4" iyz="0" izz="1e-4"/>
    </inertial>
    <visual>
      <origin rpy="0 1.5708 0" xyz="0.025 0 0"/>
      <geometry>
        <cylinder length="0.05" radius="0.01"/>
      </geometry>
      <material name="black">
        <color rgba="0.1 0.1 0.1 1.0"/>
      </material>
    </visual>
    <collision>
      <origin rpy="0 1.5708 0" xyz="0.025 0 0"/>
      <geometry>
        <cylinder length="0.05" radius="0.01"/>
      </geometry>
    </collision>
  </link>
  <!-- hip joint -->
  <joint name="leg_1_hip_joint" type="revolute">
    <origin rpy="0 0 0" xyz="0.18 0.0 0.02"/>
    <parent link="base_link"/>
    <child link="leg_1_hip_link"/>
    <axis xyz="0 0 1"/>
    <limit effort="10" lower="-1.57" upper="1.57" velocity="4"/>
  </joint>
  <!-- femur link -->
  <link name="leg_1_femur_link">
    <inertial>
      <origin rpy="0 1.5708 0" xyz="0.06 0 0"/>
      <mass value="0.08"/>
      <inertia ixx="1e-4" ixy="0" ixz="0" iyy="1e-4" iyz="0" izz="1e-4"/>
    </inertial>
    <visual>
      <origin rpy="0 1.5708 0" xyz="0.06 0 0"/>
      <geometry>
        <cylinder length="0.12" radius="0.01"/>
      </geometry>
      <material name="red">
        <color rgba="0.8 0.2 0.2 1.0"/>
      </material>
    </visual>
    <collision>
      <origin rpy="0 1.5708 0" xyz="0.06 0 0"/>
      <geometry>
        <cylinder length="0.12" radius="0.01"/>
      </geometry>
    </collision>
  </link>
  <!-- femur joint -->
  <joint name="leg_1_femur_joint" type="revolute">
    <origin rpy="0 0 0" xyz="0.05 0 0"/>
    <parent link="leg_1_hip_link"/>
    <child link="leg_1_femur_link"/>
    <axis xyz="0 1 0"/>
    <limit effort="10" lower="-1.57" upper="1.57" velocity="4"/>
  </joint>
  <!-- tibia link -->
  <link name="leg_1_tibia_link">
    <inertial>
      <origin rpy="0 1.5708 0" xyz="0.09 0 0"/>
      <mass value="0.06"/>
      <inertia ixx="1e-4" ixy="0" ixz="0" iyy="1e-4" iyz="0" izz="1e-4"/>
    </inertial>
    <visual>
      <origin rpy="0 1.5708 0" xyz="0.09 0 0"/>
      <geometry>
        <cylinder length="0.18" radius="0.01"/>
      </geometry>
      <material name="blue">
        <color rgba="0.2 0.2 0.8 1.0"/>
      </material>
    </visual>
    <collision>
      <origin rpy="0 1.5708 0" xyz="0.09 0 0"/>
      <geometry>
        <cylinder length="0.18" radius="0.01"/>
      </geometry>
    </collision>
  </link>
  <!-- tibia joint -->
  <joint name="leg_1_tibia_joint" type="revolute">
    <origin rpy="0 0 0" xyz="0.12 0 0"/>
    <parent link="leg_1_femur_link"/>
    <child link="leg_1_tibia_link"/>
    <axis xyz="0 1 0"/>
    <limit effort="10" lower="-1.57" upper="1.57" velocity="4"/>
  </joint>
  <!-- Foot link with contact sensor -->
  <link name="leg_1_foot">
    <inertial>
      <mass value="0.01"/>
      <inertia ixx="1e-6" ixy="0" ixz="0" iyy="1e-6" iyz="0" izz="1e-6"/>
    </inertial>
    <visual>
      <origin rpy="0 0 0" xyz="0 0 0"/>
      <geometry>
        <sphere radius="0.02"/>
      </geometry>
      <material name="black">
        <color rgba="0.1 0.1 0.1 1.0"/>
      </material>
    </visual>
    <collision name="leg_1_foot_collision">
      <origin rpy="0 0 0" xyz="0 0 0"/>
      <geometry>
        <sphere radius="0.02"/>
      </geometry>
      <surface>
        <friction>
          <ode>
            <mu>1.0</mu>
            <mu2>1.0</mu2>
          </ode>
        </friction>
      </surface>
    </collision>
    <sensor name="leg_1_foot_contact_sensor" type="contact">
      <always_on>true</always_on>
      <update_rate>50</update_rate>
      <topic>leg_1_foot_contact</topic>
      <plugin filename="libgz-sim-contact-system.so" name="contact_plugin"/>
    </sensor>
  </link>
  <joint name="leg_1_foot_joint" type="fixed">
    <origin rpy="0 0 0" xyz="0.18 0 0"/>
    <parent link="leg_1_tibia_link"/>
    <child link="leg_1_foot"/>
  </joint>
  <!-- hip link -->
  <link name="leg_2_hip_link">
    <inertial>
      <origin rpy="0 1.5708 0" xyz="0.025 0 0"/>
      <mass value="0.05"/>
      <inertia ixx="1e-4" ixy="0" ixz="0" iyy="1e-4" iyz="0" izz="1e-4"/>
    </inertial>
    <visual>
      <origin rpy="0 1.5708 0" xyz="0.025 0 0"/>
      <geometry>
        <cylinder length="0.05" radius="0.01"/>
      </geometry>
      <material name="black">
        <color rgba="0.1 0.1 0.1 1.0"/>
      </material>
    </visual>
    <collision>
      <origin rpy="0 1.5708 0" xyz="0.025 0 0"/>
      <geometry>
        <cylinder length="0.05" radius="0.01"/>
      </geometry>
    </collision>
  </link>
  <!-- hip joint -->
  <joint name="leg_2_hip_joint" type="revolute">
    <origin rpy="0 0 1.0472" xyz="0.09 0.156 0.02"/>
    <parent link="base_link"/>
    <child link="leg_2_hip_link"/>
    <axis xyz="0 0 1"/>
    <limit effort="10" lower="-1.57" upper="1.57" velocity="4"/>
  </joint>
  <!-- femur link -->
  <link name="leg_2_femur_link">
    <inertial>
      <origin rpy="0 1.5708 0" xyz="0.06 0 0"/>
      <mass value="0.08"/>
      <inertia ixx="1e-4" ixy="0" ixz="0" iyy="1e-4" iyz="0" izz="1e-4"/>
    </inertial>
    <visual>
      <origin rpy="0 1.5708 0" xyz="0.06 0 0"/>
      <geometry>
        <cylinder length="0.12" radius="0.01"/>
      </geometry>
      <material name="red">
        <color rgba="0.8 0.2 0.2 1.0"/>
      </material>
    </visual>
    <collision>
      <origin rpy="0 1.5708 0" xyz="0.06 0 0"/>
      <geometry>
        <cylinder length="0.12" radius="0.01"/>
      </geometry>
    </collision>
  </link>
  <!-- femur joint -->
  <joint name="leg_2_femur_joint" type="revolute">
    <origin rpy="0 0 0" xyz="0.05 0 0"/>
    <parent link="leg_2_hip_link"/>
    <child link="leg_2_femur_link"/>
    <axis xyz="0 1 0"/>
    <limit effort="10" lower="-1.57" upper="1.57" velocity="4"/>
  </joint>
  <!-- tibia link -->
  <link name="leg_2_tibia_link">
    <inertial>
      <origin rpy="0 1.5708 0" xyz="0.09 0 0"/>
      <mass value="0.06"/>
      <inertia ixx="1e-4" ixy="0" ixz="0" iyy="1e-4" iyz="0" izz="1e-4"/>
    </inertial>
    <visual>
      <origin rpy="0 1.5708 0" xyz="0.09 0 0"/>
      <geometry>
        <cylinder length="0.18" radius="0.01"/>
      </geometry>
      <material name="blue">
        <color rgba="0.2 0.2 0.8 1.0"/>
      </material>
    </visual>
    <collision>
      <origin rpy="0 1.5708 0" xyz="0.09 0 0"/>
      <geometry>
        <cylinder length="0.18" radius="0.01"/>
      </geometry>
    </collision>
  </link>
  <!-- tibia joint -->
  <joint name="leg_2_tibia_joint" type="revolute">
    <origin rpy="0 0 0" xyz="0.12 0 0"/>
    <parent link="leg_2_femur_link"/>
    <child link="leg_2_tibia_link"/>
    <axis xyz="0 1 0"/>
    <limit effort="10" lower="-1.57" upper="1.57" velocity="4"/>
  </joint>
  <!-- Foot link with contact sensor -->
  <link name="leg_2_foot">
    <inertial>
      <mass value="0.01"/>
      <inertia ixx="1e-6" ixy="0" ixz="0" iyy="1e-6" iyz="0" izz="1e-6"/>
    </inertial>
    <visual>
      <origin rpy="0 0 0" xyz="0 0 0"/>
      <geometry>
        <sphere radius="0.02"/>
      </geometry>
      <material name="black">
        <color rgba="0.1 0.1 0.1 1.0"/>
      </material>
    </visual>
    <collision name="leg_2_foot_collision">
      <origin rpy="0 0 0" xyz="0 0 0"/>
      <geometry>
        <sphere radius="0.02"/>
      </geometry>
      <surface>
        <friction>
          <ode>
            <mu>1.0</mu>
            <mu2>1.0</mu2>
          </ode>
        </friction>
      </surface>
    </collision>
    <sensor name="leg_2_foot_contact_sensor" type="contact">
      <always_on>true</always_on>
      <update_rate>50</update_rate>
      <topic>leg_2_foot_contact</topic>
      <plugin filename="libgz-sim-contact-system.so" name="contact_plugin"/>
    </sensor>
  </link>
  <joint name="leg_2_foot_joint" type="fixed">
    <origin rpy="0 0 0" xyz="0.18 0 0"/>
    <parent link="leg_2_tibia_link"/>
    <child link="leg_2_foot"/>
  </joint>
  <!-- hip link -->
  <link name="leg_3_hip_link">
    <inertial>
      <origin rpy="0 1.5708 0" xyz="0.025 0 0"/>
      <mass value="0.05"/>
      <inertia ixx="1e-4" ixy="0" ixz="0" iyy="1e-4" iyz="0" izz="1e-4"/>
    </inertial>
    <visual>
      <origin rpy="0 1.5708 0" xyz="0.025 0 0"/>
      <geometry>
        <cylinder length="0.05" radius="0.01"/>
      </geometry>
      <material name="black">
        <color rgba="0.1 0.1 0.1 1.0"/>
      </material>
    </visual>
    <collision>
      <origin rpy="0 1.5708 0" xyz="0.025 0 0"/>
      <geometry>
        <cylinder length="0.05" radius="0.01"/>
      </geometry>
    </collision>
  </link>
  <!-- hip joint -->
  <joint name="leg_3_hip_joint" type="revolute">
    <origin rpy="0 0 2.0944" xyz="-0.09 0.156 0.02"/>
    <parent link="base_link"/>
    <child link="leg_3_hip_link"/>
    <axis xyz="0 0 1"/>
    <limit effort="10" lower="-1.57" upper="1.57" velocity="4"/>
  </joint>
  <!-- femur link -->
  <link name="leg_3_femur_link">
    <inertial>
      <origin rpy="0 1.5708 0" xyz="0.06 0 0"/>
      <mass value="0.08"/>
      <inertia ixx="1e-4" ixy="0" ixz="0" iyy="1e-4" iyz="0" izz="1e-4"/>
    </inertial>
    <visual>
      <origin rpy="0 1.5708 0" xyz="0.06 0 0"/>
      <geometry>
        <cylinder length="0.12" radius="0.01"/>
      </geometry>
      <material name="red">
        <color rgba="0.8 0.2 0.2 1.0"/>
      </material>
    </visual>
    <collision>
      <origin rpy="0 1.5708 0" xyz="0.06 0 0"/>
      <geometry>
        <cylinder length="0.12" radius="0.01"/>
      </geometry>
    </collision>
  </link>
  <!-- femur joint -->
  <joint name="leg_3_femur_joint" type="revolute">
    <origin rpy="0 0 0" xyz="0.05 0 0"/>
    <parent link="leg_3_hip_link"/>
    <child link="leg_3_femur_link"/>
    <axis xyz="0 1 0"/>
    <limit effort="10" lower="-1.57" upper="1.57" velocity="4"/>
  </joint>
  <!-- tibia link -->
  <link name="leg_3_tibia_link">
    <inertial>
      <origin rpy="0 1.5708 0" xyz="0.09 0 0"/>
      <mass value="0.06"/>
      <inertia ixx="1e-4" ixy="0" ixz="0" iyy="1e-4" iyz="0" izz="1e-4"/>
    </inertial>
    <visual>
      <origin rpy="0 1.5708 0" xyz="0.09 0 0"/>
      <geometry>
        <cylinder length="0.18" radius="0.01"/>
      </geometry>
      <material name="blue">
        <color rgba="0.2 0.2 0.8 1.0"/>
      </material>
    </visual>
    <collision>
      <origin rpy="0 1.5708 0" xyz="0.09 0 0"/>
      <geometry>
        <cylinder length="0.18" radius="0.01"/>
      </geometry>
    </collision>
  </link>
  <!-- tibia joint -->
  <joint name="leg_3_tibia_joint" type="revolute">
    <origin rpy="0 0 0" xyz="0.12 0 0"/>
    <parent link="leg_3_femur_link"/>
    <child link="leg_3_tibia_link"/>
    <axis xyz="0 1 0"/>
    <limit effort="10" lower="-1.57" upper="1.57" velocity="4"/>
  </joint>
  <!-- Foot link with contact sensor -->
  <link name="leg_3_foot">
    <inertial>
      <mass value="0.01"/>
      <inertia ixx="1e-6" ixy="0" ixz="0" iyy="1e-6" iyz="0" izz="1e-6"/>
    </inertial>
    <visual>
      <origin rpy="0 0 0" xyz="0 0 0"/>
      <geometry>
        <sphere radius="0.02"/>
      </geometry>
      <material name="black">
        <color rgba="0.1 0.1 0.1 1.0"/>
      </material>
    </visual>
    <collision name="leg_3_foot_collision">
      <origin rpy="0 0 0" xyz="0 0 0"/>
      <geometry>
        <sphere radius="0.02"/>
      </geometry>
      <surface>
        <friction>
          <ode>
            <mu>1.0</mu>
            <mu2>1.0</mu2>
          </ode>
        </friction>
      </surface>
    </collision>
    <sensor name="leg_3_foot_contact_sensor" type="contact">
      <always_on>true</always_on>
      <update_rate>50</update_rate>
      <topic>leg_3_foot_contact</topic>
      <plugin filename="libgz-sim-contact-system.so" name="contact_plugin"/>
    </sensor>
  </link>
  <joint name="leg_3_foot_joint" type="fixed">
    <origin rpy="0 0 0" xyz="0.18 0 0"/>
    <parent link="leg_3_tibia_link"/>
    <child link="leg_3_foot"/>
  </joint>
  <!-- hip link -->
  <link name="leg_4_hip_link">
    <inertial>
      <origin rpy="0 1.5708 0" xyz="0.025 0 0"/>
      <mass value="0.05"/>
      <inertia ixx="1e-4" ixy="0" ixz="0" iyy="1e-4" iyz="0" izz="1e-4"/>
    </inertial>
    <visual>
      <origin rpy="0 1.5708 0" xyz="0.025 0 0"/>
      <geometry>
        <cylinder length="0.05" radius="0.01"/>
      </geometry>
      <material name="black">
        <color rgba="0.1 0.1 0.1 1.0"/>
      </material>
    </visual>
    <collision>
      <origin rpy="0 1.5708 0" xyz="0.025 0 0"/>
      <geometry>
        <cylinder length="0.05" radius="0.01"/>
      </geometry>
    </collision>
  </link>
  <!-- hip joint -->
  <joint name="leg_4_hip_joint" type="revolute">
    <origin rpy="0 0 3.14159" xyz="-0.18 0.0 0.02"/>
    <parent link="base_link"/>
    <child link="leg_4_hip_link"/>
    <axis xyz="0 0 1"/>
    <limit effort="10" lower="-1.57" upper="1.57" velocity="4"/>
  </joint>
  <!-- femur link -->
  <link name="leg_4_femur_link">
    <inertial>
      <origin rpy="0 1.5708 0" xyz="0.06 0 0"/>
      <mass value="0.08"/>
      <inertia ixx="1e-4" ixy="0" ixz="0" iyy="1e-4" iyz="0" izz="1e-4"/>
    </inertial>
    <visual>
      <origin rpy="0 1.5708 0" xyz="0.06 0 0"/>
      <geometry>
        <cylinder length="0.12" radius="0.01"/>
      </geometry>
      <material name="red">
        <color rgba="0.8 0.2 0.2 1.0"/>
      </material>
    </visual>
    <collision>
      <origin rpy="0 1.5708 0" xyz="0.06 0 0"/>
      <geometry>
        <cylinder length="0.12" radius="0.01"/>
      </geometry>
    </collision>
  </link>
  <!-- femur joint -->
  <joint name="leg_4_femur_joint" type="revolute">
    <origin rpy="0 0 0" xyz="0.05 0 0"/>
    <parent link="leg_4_hip_link"/>
    <child link="leg_4_femur_link"/>
    <axis xyz="0 1 0"/>
    <limit effort="10" lower="-1.57" upper="1.57" velocity="4"/>
  </joint>
  <!-- tibia link -->
  <link name="leg_4_tibia_link">
    <inertial>
      <origin rpy="0 1.5708 0" xyz="0.09 0 0"/>
      <mass value="0.06"/>
      <inertia ixx="1e-4" ixy="0" ixz="0" iyy="1e-4" iyz="0" izz="1e-4"/>
    </inertial>
    <visual>
      <origin rpy="0 1.5708 0" xyz="0.09 0 0"/>
      <geometry>
        <cylinder length="0.18" radius="0.01"/>
      </geometry>
      <material name="blue">
        <color rgba="0.2 0.2 0.8 1.0"/>
      </material>
    </visual>
    <collision>
      <origin rpy="0 1.5708 0" xyz="0.09 0 0"/>
      <geometry>
        <cylinder length="0.18" radius="0.01"/>
      </geometry>
    </collision>
  </link>
  <!-- tibia joint -->
  <joint name="leg_4_tibia_joint" type="revolute">
    <origin rpy="0 0 0" xyz="0.12 0 0"/>
    <parent link="leg_4_femur_link"/>
    <child link="leg_4_tibia_link"/>
    <axis xyz="0 1 0"/>
    <limit effort="10" lower="-1.57" upper="1.57" velocity="4"/>
  </joint>
  <!-- Foot link with contact sensor -->
  <link name="leg_4_foot">
    <inertial>
      <mass value="0.01"/>
      <inertia ixx="1e-6" ixy="0" ixz="0" iyy="1e-6" iyz="0" izz="1e-6"/>
    </inertial>
    <visual>
      <origin rpy="0 0 0" xyz="0 0 0"/>
      <geometry>
        <sphere radius="0.02"/>
      </geometry>
      <material name="black">
        <color rgba="0.1 0.1 0.1 1.0"/>
      </material>
    </visual>
    <collision name="leg_4_foot_collision">
      <origin rpy="0 0 0" xyz="0 0 0"/>
      <geometry>
        <sphere radius="0.02"/>
      </geometry>
      <surface>
        <friction>
          <ode>
            <mu>1.0</mu>
            <mu2>1.0</mu2>
          </ode>
        </friction>
      </surface>
    </collision>
    <sensor name="leg_4_foot_contact_sensor" type="contact">
      <always_on>true</always_on>
      <update_rate>50</update_rate>
      <topic>leg_4_foot_contact</topic>
      <plugin filename="libgz-sim-contact-system.so" name="contact_plugin"/>
    </sensor>
  </link>
  <joint name="leg_4_foot_joint" type="fixed">
    <origin rpy="0 0 0" xyz="0.18 0 0"/>
    <parent link="leg_4_tibia_link"/>
    <child link="leg_4_foot"/>
  </joint>
  <!-- hip link -->
  <link name="leg_5_hip_link">
    <inertial>
      <origin rpy="0 1.5708 0" xyz="0.025 0 0"/>
      <mass value="0.05"/>
      <inertia ixx="1e-4" ixy="0" ixz="0" iyy="1e-4" iyz="0" izz="1e-4"/>
    </inertial>
    <visual>
      <origin rpy="0 1.5708 0" xyz="0.025 0 0"/>
      <geometry>
        <cylinder length="0.05" radius="0.01"/>
      </geometry>
      <material name="black">
        <color rgba="0.1 0.1 0.1 1.0"/>
      </material>
    </visual>
    <collision>
      <origin rpy="0 1.5708 0" xyz="0.025 0 0"/>
      <geometry>
        <cylinder length="0.05" radius="0.01"/>
      </geometry>
    </collision>
  </link>
  <!-- hip joint -->
  <joint name="leg_5_hip_joint" type="revolute">
    <origin rpy="0 0 -2.0944" xyz="-0.09 -0.156 0.02"/>
    <parent link="base_link"/>
    <child link="leg_5_hip_link"/>
    <axis xyz="0 0 1"/>
    <limit effort="10" lower="-1.57" upper="1.57" velocity="4"/>
  </joint>
  <!-- femur link -->
  <link name="leg_5_femur_link">
    <inertial>
      <origin rpy="0 1.5708 0" xyz="0.06 0 0"/>
      <mass value="0.08"/>
      <inertia ixx="1e-4" ixy="0" ixz="0" iyy="1e-4" iyz="0" izz="1e-4"/>
    </inertial>
    <visual>
      <origin rpy="0 1.5708 0" xyz="0.06 0 0"/>
      <geometry>
        <cylinder length="0.12" radius="0.01"/>
      </geometry>
      <material name="red">
        <color rgba="0.8 0.2 0.2 1.0"/>
      </material>
    </visual>
    <collision>
      <origin rpy="0 1.5708 0" xyz="0.06 0 0"/>
      <geometry>
        <cylinder length="0.12" radius="0.01"/>
      </geometry>
    </collision>
  </link>
  <!-- femur joint -->
  <joint name="leg_5_femur_joint" type="revolute">
    <origin rpy="0 0 0" xyz="0.05 0 0"/>
    <parent link="leg_5_hip_link"/>
    <child link="leg_5_femur_link"/>
    <axis xyz="0 1 0"/>
    <limit effort="10" lower="-1.57" upper="1.57" velocity="4"/>
  </joint>
  <!-- tibia link -->
  <link name="leg_5_tibia_link">
    <inertial>
      <origin rpy="0 1.5708 0" xyz="0.09 0 0"/>
      <mass value="0.06"/>
      <inertia ixx="1e-4" ixy="0" ixz="0" iyy="1e-4" iyz="0" izz="1e-4"/>
    </inertial>
    <visual>
      <origin rpy="0 1.5708 0" xyz="0.09 0 0"/>
      <geometry>
        <cylinder length="0.18" radius="0.01"/>
      </geometry>
      <material name="blue">
        <color rgba="0.2 0.2 0.8 1.0"/>
      </material>
    </visual>
    <collision>
      <origin rpy="0 1.5708 0" xyz="0.09 0 0"/>
      <geometry>
        <cylinder length="0.18" radius="0.01"/>
      </geometry>
    </collision>
  </link>
  <!-- tibia joint -->
  <joint name="leg_5_tibia_joint" type="revolute">
    <origin rpy="0 0 0" xyz="0.12 0 0"/>
    <parent link="leg_5_femur_link"/>
    <child link="leg_5_tibia_link"/>
    <axis xyz="0 1 0"/>
    <limit effort="10" lower="-1.57" upper="1.57" velocity="4"/>
  </joint>
  <!-- Foot link with contact sensor -->
  <link name="leg_5_foot">
    <inertial>
      <mass value="0.01"/>
      <inertia ixx="1e-6" ixy="0" ixz="0" iyy="1e-6" iyz="0" izz="1e-6"/>
    </inertial>
    <visual>
      <origin rpy="0 0 0" xyz="0 0 0"/>
      <geometry>
        <sphere radius="0.02"/>
      </geometry>
      <material name="black">
        <color rgba="0.1 0.1 0.1 1.0"/>
      </material>
    </visual>
    <collision name="leg_5_foot_collision">
      <origin rpy="0 0 0" xyz="0 0 0"/>
      <geometry>
        <sphere radius="0.02"/>
      </geometry>
      <surface>
        <friction>
          <ode>
            <mu>1.0</mu>
            <mu2>1.0</mu2>
          </ode>
        </friction>
      </surface>
    </collision>
    <sensor name="leg_5_foot_contact_sensor" type="contact">
      <always_on>true</always_on>
      <update_rate>50</update_rate>
      <topic>leg_5_foot_contact</topic>
      <plugin filename="libgz-sim-contact-system.so" name="contact_plugin"/>
    </sensor>
  </link>
  <joint name="leg_5_foot_joint" type="fixed">
    <origin rpy="0 0 0" xyz="0.18 0 0"/>
    <parent link="leg_5_tibia_link"/>
    <child link="leg_5_foot"/>
  </joint>
  <!-- hip link -->
  <link name="leg_6_hip_link">
    <inertial>
      <origin rpy="0 1.5708 0" xyz="0.025 0 0"/>
      <mass value="0.05"/>
      <inertia ixx="1e-4" ixy="0" ixz="0" iyy="1e-4" iyz="0" izz="1e-4"/>
    </inertial>
    <visual>
      <origin rpy="0 1.5708 0" xyz="0.025 0 0"/>
      <geometry>
        <cylinder length="0.05" radius="0.01"/>
      </geometry>
      <material name="black">
        <color rgba="0.1 0.1 0.1 1.0"/>
      </material>
    </visual>
    <collision>
      <origin rpy="0 1.5708 0" xyz="0.025 0 0"/>
      <geometry>
        <cylinder length="0.05" radius="0.01"/>
      </geometry>
    </collision>
  </link>
  <!-- hip joint -->
  <joint name="leg_6_hip_joint" type="revolute">
    <origin rpy="0 0 -1.0472" xyz="0.09 -0.156 0.02"/>
    <parent link="base_link"/>
    <child link="leg_6_hip_link"/>
    <axis xyz="0 0 1"/>
    <limit effort="10" lower="-1.57" upper="1.57" velocity="4"/>
  </joint>
  <!-- femur link -->
  <link name="leg_6_femur_link">
    <inertial>
      <origin rpy="0 1.5708 0" xyz="0.06 0 0"/>
      <mass value="0.08"/>
      <inertia ixx="1e-4" ixy="0" ixz="0" iyy="1e-4" iyz="0" izz="1e-4"/>
    </inertial>
    <visual>
      <origin rpy="0 1.5708 0" xyz="0.06 0 0"/>
      <geometry>
        <cylinder length="0.12" radius="0.01"/>
      </geometry>
      <material name="red">
        <color rgba="0.8 0.2 0.2 1.0"/>
      </material>
    </visual>
    <collision>
      <origin rpy="0 1.5708 0" xyz="0.06 0 0"/>
      <geometry>
        <cylinder length="0.12" radius="0.01"/>
      </geometry>
    </collision>
  </link>
  <!-- femur joint -->
  <joint name="leg_6_femur_joint" type="revolute">
    <origin rpy="0 0 0" xyz="0.05 0 0"/>
    <parent link="leg_6_hip_link"/>
    <child link="leg_6_femur_link"/>
    <axis xyz="0 1 0"/>
    <limit effort="10" lower="-1.57" upper="1.57" velocity="4"/>
  </joint>
  <!-- tibia link -->
  <link name="leg_6_tibia_link">
    <inertial>
      <origin rpy="0 1.5708 0" xyz="0.09 0 0"/>
      <mass value="0.06"/>
      <inertia ixx="1e-4" ixy="0" ixz="0" iyy="1e-4" iyz="0" izz="1e-4"/>
    </inertial>
    <visual>
      <origin rpy="0 1.5708 0" xyz="0.09 0 0"/>
      <geometry>
        <cylinder length="0.18" radius="0.01"/>
      </geometry>
      <material name="blue">
        <color rgba="0.2 0.2 0.8 1.0"/>
      </material>
    </visual>
    <collision>
      <origin rpy="0 1.5708 0" xyz="0.09 0 0"/>
      <geometry>
        <cylinder length="0.18" radius="0.01"/>
      </geometry>
    </collision>
  </link>
  <!-- tibia joint -->
  <joint name="leg_6_tibia_joint" type="revolute">
    <origin rpy="0 0 0" xyz="0.12 0 0"/>
    <parent link="leg_6_femur_link"/>
    <child link="leg_6_tibia_link"/>
    <axis xyz="0 1 0"/>
    <limit effort="10" lower="-1.57" upper="1.57" velocity="4"/>
  </joint>
  <!-- Foot link with contact sensor -->
  <link name="leg_6_foot">
    <inertial>
      <mass value="0.01"/>
      <inertia ixx="1e-6" ixy="0" ixz="0" iyy="1e-6" iyz="0" izz="1e-6"/>
    </inertial>
    <visual>
      <origin rpy="0 0 0" xyz="0 0 0"/>
      <geometry>
        <sphere radius="0.02"/>
      </geometry>
      <material name="black">
        <color rgba="0.1 0.1 0.1 1.0"/>
      </material>
    </visual>
    <collision name="leg_6_foot_collision">
      <origin rpy="0 0 0" xyz="0 0 0"/>
      <geometry>
        <sphere radius="0.02"/>
      </geometry>
      <surface>
        <friction>
          <ode>
            <mu>1.0</mu>
            <mu2>1.0</mu2>
          </ode>
        </friction>
      </surface>
    </collision>
    <sensor name="leg_6_foot_contact_sensor" type="contact">
      <always_on>true</always_on>
      <update_rate>50</update_rate>
      <topic>leg_6_foot_contact</topic>
      <plugin filename="libgz-sim-contact-system.so" name="contact_plugin"/>
    </sensor>
  </link>
  <joint name="leg_6_foot_joint" type="fixed">
    <origin rpy="0 0 0" xyz="0.18 0 0"/>
    <parent link="leg_6_tibia_link"/>
    <child link="leg_6_foot"/>
  </joint>
  <!-- ros2_control hardware interface -->
  <ros2_control name="HexapodSystem" type="system">
    <hardware>
      <!-- Using the generic demo hardware plugin for simulation/testing -->
      <plugin>gz_ros2_control/GazeboSimSystem</plugin>
      <!-- Optional parameters (safe defaults for virtual hardware) -->
      <param name="example_param_hw_start_duration_sec">0.0</param>
      <param name="example_param_hw_stop_duration_sec">0.0</param>
      <param name="example_param_hw_slowdown">1.0</param>
    </hardware>
    <!-- ========== LEG 1 ========== -->
    <joint name="leg_1_hip_joint">
      <command_interface name="position"/>
      <state_interface name="position"/>
      <state_interface name="velocity"/>
    </joint>
    <joint name="leg_1_femur_joint">
      <command_interface name="position"/>
      <state_interface name="position"/>
      <state_interface name="velocity"/>
    </joint>
    <joint name="leg_1_tibia_joint">
      <command_interface name="position"/>
      <state_interface name="position"/>
      <state_interface name="velocity"/>
    </joint>
    <!-- ========== LEG 2 ========== -->
    <joint name="leg_2_hip_joint">
      <command_interface name="position"/>
      <state_interface name="position"/>
      <state_interface name="velocity"/>
    </joint>
    <joint name="leg_2_femur_joint">
      <command_interface name="position"/>
      <state_interface name="position"/>
      <state_interface name="velocity"/>
    </joint>
    <joint name="leg_2_tibia_joint">
      <command_interface name="position"/>
      <state_interface name="position"/>
      <state_interface name="velocity"/>
    </joint>
    <!-- ========== LEG 3 ========== -->
    <joint name="leg_3_hip_joint">
      <command_interface name="position"/>
      <state_interface name="position"/>
      <state_interface name="velocity"/>
    </joint>
    <joint name="leg_3_femur_joint">
      <command_interface name="position"/>
      <state_interface name="position"/>
      <state_interface name="velocity"/>
    </joint>
    <joint name="leg_3_tibia_joint">
      <command_interface name="position"/>
      <state_interface name="position"/>
      <state_interface name="velocity"/>
    </joint>
    <!-- ========== LEG 4 ========== -->
    <joint name="leg_4_hip_joint">
      <command_interface name="position"/>
      <state_interface name="position"/>
      <state_interface name="velocity"/>
    </joint>
    <joint name="leg_4_femur_joint">
      <command_interface name="position"/>
      <state_interface name="position"/>
      <state_interface name="velocity"/>
    </joint>
    <joint name="leg_4_tibia_joint">
      <command_interface name="position"/>
      <state_interface name="position"/>
      <state_interface name="velocity"/>
    </joint>
    <!-- ========== LEG 5 ========== -->
    <joint name="leg_5_hip_joint">
      <command_interface name="position"/>
      <state_interface name="position"/>
      <state_interface name="velocity"/>
    </joint>
    <joint name="leg_5_femur_joint">
      <command_interface name="position"/>
      <state_interface name="position"/>
      <state_interface name="velocity"/>
    </joint>
    <joint name="leg_5_tibia_joint">
      <command_interface name="position"/>
      <state_interface name="position"/>
      <state_interface name="velocity"/>
    </joint>
    <!-- ========== LEG 6 ========== -->
    <joint name="leg_6_hip_joint">
      <command_interface name="position"/>
      <state_interface name="position"/>
      <state_interface name="velocity"/>
    </joint>
    <joint name="leg_6_femur_joint">
      <command_interface name="position"/>
      <state_interface name="position"/>
      <state_interface name="velocity"/>
    </joint>
    <joint name="leg_6_tibia_joint">
      <command_interface name="position"/>
      <state_interface name="position"/>
      <state_interface name="velocity"/>
    </joint>
  </ros2_control>
  <!-- ros2_control plugin for Gazebo Harmonic -->
  <gazebo>
    <plugin filename="libgz_ros2_control-system.so" name="gz_ros2_control::GazeboSimROS2ControlPlugin">
      <parameters>/home/gautam/hexapod_ws/install/hexapod_ws/share/hexapod_ws/config/parameters.yaml</parameters>
    </plugin>
  </gazebo>
</robot>
